<sdf version='1.11'>
  <model name='manipulator'>
    <joint name='dummy_joint' type='fixed'>
      <pose relative_to='__model__'>0 0 0 0 0 0</pose>
      <parent>world</parent>
      <child>base_link</child>
    </joint>
    <link name='base_link'>
      <pose relative_to='dummy_joint'>0 0 0 0 0 0</pose>
      <inertial>
        <pose>0.0021253000000000001 0.047934999999999998 0.027764 0 0 0</pose>
        <mass>0.089599999999999999</mass>
        <inertia>
          <ixx>5.041e-05</ixx>
          <ixy>-8.5548000000000006e-08</ixy>
          <ixz>3.2278e-08</ixz>
          <iyy>6.5382000000000005e-05</iyy>
          <iyz>4.1605000000000003e-12</iyz>
          <izz>0.00010836</izz>
        </inertia>
      </inertial>
      <collision name='base_link_collision'>
        <pose>0 0 0 0 0 0</pose>
        <geometry>
          <mesh>
            <scale>1 1 1</scale>
            <uri>/home/proto/MARIO/3_simulation_gazebo/meshes/base_link.STL</uri>
          </mesh>
        </geometry>
      </collision>
      <visual name='base_link_visual'>
        <pose>0 0 0 0 0 0</pose>
        <geometry>
          <mesh>
            <scale>1 1 1</scale>
            <uri>/home/proto/MARIO/3_simulation_gazebo/meshes/base_link.STL</uri>
          </mesh>
        </geometry>
        <material>
          <diffuse>0.784312487 0.784312487 0.784312487 1</diffuse>
          <ambient>0.784312487 0.784312487 0.784312487 1</ambient>
        </material>
      </visual>
    </link>
    <joint name='joint_1' type='revolute'>
      <pose relative_to='base_link'>-0.0030195999999999999 0.046937 0.063500000000000001 0 0 0</pose>
      <parent>base_link</parent>
      <child>link_1</child>
      <axis>
        <xyz>0 0 1</xyz>
        <limit>
          <lower>0</lower>
          <upper>3.1400000000000001</upper>
          <effort>1</effort>
          <velocity>1</velocity>
        </limit>
        <dynamics>
          <spring_reference>0</spring_reference>
          <spring_stiffness>0</spring_stiffness>
        </dynamics>
      </axis>
    </joint>
    <link name='link_1'>
      <pose relative_to='joint_1'>0 0 0 0 0 0</pose>
      <inertial>
        <pose>-0.00017375999999999999 -0.015932999999999999 0.017371000000000001 0 0 0</pose>
        <mass>0.024846</mass>
        <inertia>
          <ixx>3.4858000000000002e-06</ixx>
          <ixy>2.3072e-08</ixy>
          <ixz>-6.6523999999999997e-10</ixz>
          <iyy>7.2894e-06</iyy>
          <iyz>-1.2663000000000001e-08</iyz>
          <izz>7.0044999999999996e-06</izz>
        </inertia>
      </inertial>
      <collision name='link_1_collision'>
        <pose>0 0 0 0 0 0</pose>
        <geometry>
          <mesh>
            <scale>1 1 1</scale>
            <uri>/home/proto/MARIO/3_simulation_gazebo/meshes/link_1.STL</uri>
          </mesh>
        </geometry>
      </collision>
      <visual name='link_1_visual'>
        <pose>0 0 0 0 0 0</pose>
        <geometry>
          <mesh>
            <scale>1 1 1</scale>
            <uri>/home/proto/MARIO/3_simulation_gazebo/meshes/link_1.STL</uri>
          </mesh>
        </geometry>
        <material>
          <diffuse>0.990199983 1 1 1</diffuse>
          <ambient>0.990199983 1 1 1</ambient>
        </material>
      </visual>
    </link>
    <joint name='joint_2' type='revolute'>
      <pose relative_to='link_1'>0.00031511000000000001 -0.0095653000000000005 0.034407 0 0 0</pose>
      <parent>link_1</parent>
      <child>link_2</child>
      <axis>
        <xyz>0 -1 0</xyz>
        <limit>
          <lower>0</lower>
          <upper>3.1400000000000001</upper>
          <effort>1</effort>
          <velocity>1</velocity>
        </limit>
        <dynamics>
          <spring_reference>0</spring_reference>
          <spring_stiffness>0</spring_stiffness>
        </dynamics>
      </axis>
    </joint>
    <link name='link_2'>
      <pose relative_to='joint_2'>0 0 0 0 0 0</pose>
      <inertial>
        <pose>0.051889999999999999 -0.0024721000000000001 -0.0024700999999999998 0 0 0</pose>
        <mass>0.016330000000000001</mass>
        <inertia>
          <ixx>6.5489999999999997e-07</ixx>
          <ixy>1.9218e-08</ixy>
          <ixz>2.8286999999999999e-07</ixz>
          <iyy>5.9038000000000001e-06</iyy>
          <iyz>-1.0049999999999999e-09</iyz>
          <izz>5.3932000000000003e-06</izz>
        </inertia>
      </inertial>
      <collision name='link_2_collision'>
        <pose>0 0 0 0 0 0</pose>
        <geometry>
          <mesh>
            <scale>1 1 1</scale>
            <uri>/home/proto/MARIO/3_simulation_gazebo/meshes/link_2.STL</uri>
          </mesh>
        </geometry>
      </collision>
      <visual name='link_2_visual'>
        <pose>0 0 0 0 0 0</pose>
        <geometry>
          <mesh>
            <scale>1 1 1</scale>
            <uri>/home/proto/MARIO/3_simulation_gazebo/meshes/link_2.STL</uri>
          </mesh>
        </geometry>
        <material>
          <diffuse>0.990199983 1 1 1</diffuse>
          <ambient>0.990199983 1 1 1</ambient>
        </material>
      </visual>
    </link>
    <joint name='joint_3' type='revolute'>
      <pose relative_to='link_2'>0.071530999999999997 0.011279000000000001 -0.0041348000000000001 0 0 0</pose>
      <parent>link_2</parent>
      <child>link_3</child>
      <axis>
        <xyz>0 -1 0</xyz>
        <limit>
          <lower>0</lower>
          <upper>3.1400000000000001</upper>
          <effort>1</effort>
          <velocity>1</velocity>
        </limit>
        <dynamics>
          <spring_reference>0</spring_reference>
          <spring_stiffness>0</spring_stiffness>
        </dynamics>
      </axis>
    </joint>
    <link name='link_3'>
      <pose relative_to='joint_3'>0 0 0 0 0 0</pose>
      <inertial>
        <pose>0.0037356999999999998 -0.001707 -0.066045000000000006 0 0 0</pose>
        <mass>0.019923</mass>
        <inertia>
          <ixx>5.6377999999999996e-06</ixx>
          <ixy>3.6797e-09</ixy>
          <ixz>4.2574e-07</ixz>
          <iyy>5.2183999999999999e-06</iyy>
          <iyz>6.2841e-08</iyz>
          <izz>1.4011e-06</izz>
        </inertia>
      </inertial>
      <collision name='link_3_collision'>
        <pose>0 0 0 0 0 0</pose>
        <geometry>
          <mesh>
            <scale>1 1 1</scale>
            <uri>/home/proto/MARIO/3_simulation_gazebo/meshes/link_3.STL</uri>
          </mesh>
        </geometry>
      </collision>
      <visual name='link_3_visual'>
        <pose>0 0 0 0 0 0</pose>
        <geometry>
          <mesh>
            <scale>1 1 1</scale>
            <uri>/home/proto/MARIO/3_simulation_gazebo/meshes/link_3.STL</uri>
          </mesh>
        </geometry>
        <material>
          <diffuse>0.990199983 1 1 1</diffuse>
          <ambient>0.990199983 1 1 1</ambient>
        </material>
      </visual>
    </link>
    <joint name='joint_4' type='revolute'>
      <pose relative_to='link_3'>0.020924999999999999 -0.013767 -0.090330999999999995 0 0 0</pose>
      <parent>link_3</parent>
      <child>claw_right</child>
      <axis>
        <xyz>-1 0 0</xyz>
        <limit>
          <lower>0</lower>
          <upper>0.80000000000000004</upper>
          <effort>1</effort>
          <velocity>1</velocity>
        </limit>
        <dynamics>
          <spring_reference>0</spring_reference>
          <spring_stiffness>0</spring_stiffness>
        </dynamics>
      </axis>
    </joint>
    <link name='claw_right'>
      <pose relative_to='joint_4'>0 0 0 0 0 0</pose>
      <inertial>
        <pose>0.0018121999999999999 0.0028283000000000002 -0.0079471999999999998 0 0 0</pose>
        <mass>0.013225000000000001</mass>
        <inertia>
          <ixx>3.2337999999999999e-06</ixx>
          <ixy>-2.8171999999999999e-08</ixy>
          <ixz>2.6752e-07</ixz>
          <iyy>2.7116e-06</iyy>
          <iyz>2.4983000000000001e-07</iyz>
          <izz>5.8457999999999996e-07</izz>
        </inertia>
      </inertial>
      <collision name='claw_right_collision'>
        <pose>0 0 0 0 0 0</pose>
        <geometry>
          <mesh>
            <scale>1 1 1</scale>
            <uri>/home/proto/MARIO/3_simulation_gazebo/meshes/claw_right.STL</uri>
          </mesh>
        </geometry>
      </collision>
      <visual name='claw_right_visual'>
        <pose>0 0 0 0 0 0</pose>
        <geometry>
          <mesh>
            <scale>1 1 1</scale>
            <uri>/home/proto/MARIO/3_simulation_gazebo/meshes/claw_right.STL</uri>
          </mesh>
        </geometry>
        <material>
          <diffuse>0.970587492 0.946075022 0.921562433 1</diffuse>
          <ambient>0.970587492 0.946075022 0.921562433 1</ambient>
        </material>
      </visual>
    </link>
    <joint name='joint_5' type='revolute'>
      <pose relative_to='link_3'>0.0091023000000000007 0.0182709 -0.090511999999999995 0 0 0</pose>
      <parent>link_3</parent>
      <child>claw_left</child>
      <axis>
        <xyz>1 0 0</xyz>
        <limit>
          <lower>0</lower>
          <upper>0.80000000000000004</upper>
          <effort>1</effort>
          <velocity>1</velocity>
        </limit>
        <dynamics>
          <spring_reference>0</spring_reference>
          <spring_stiffness>0</spring_stiffness>
        </dynamics>
      </axis>
    </joint>
    <link name='claw_left'>
      <pose relative_to='joint_5'>0 0 0 0 0 0</pose>
      <inertial>
        <pose>0.013771 0.012345 -0.01495 0 0 0</pose>
        <mass>0.013641</mass>
        <inertia>
          <ixx>3.4174999999999999e-06</ixx>
          <ixy>3.0134e-09</ixy>
          <ixz>2.7613000000000002e-07</ixz>
          <iyy>2.8184e-06</iyy>
          <iyz>-6.8498999999999997e-08</iyz>
          <izz>6.6306000000000001e-07</izz>
        </inertia>
      </inertial>
      <collision name='claw_left_collision'>
        <pose>0 0 0 0 0 0</pose>
        <geometry>
          <mesh>
            <scale>1 1 1</scale>
            <uri>/home/proto/MARIO/3_simulation_gazebo/meshes/claw_left.STL</uri>
          </mesh>
        </geometry>
      </collision>
      <visual name='claw_left_visual'>
        <pose>0 -0.014 0.0074999999999999997 0 0 0</pose>
        <geometry>
          <mesh>
            <scale>1 1 1</scale>
            <uri>/home/proto/MARIO/3_simulation_gazebo/meshes/claw_left.STL</uri>
          </mesh>
        </geometry>
        <material>
          <diffuse>0.970587492 0.946075022 0.921562433 1</diffuse>
          <ambient>0.970587492 0.946075022 0.921562433 1</ambient>
        </material>
      </visual>
    </link>
    <plugin filename="libgz_ros2_control-system.so" name="gz_ros2_control::GazeboSimROS2ControlPlugin">     
    	<robot_sim_type>gz_ros2_control/GazeboSystem</robot_sim_type>
      <parameters>$(find simulation_gazebo)/config/manipulator.yaml</parameters>
    </plugin>
  </model>
</sdf>
